Workbook

Sheet 贾总
A1: 成都国圣工业有限公司（五星花）送货单
A2: 购货单位： 贾总 联系人：贾总 2026年01月22日 订单编号：26-010062A
A3: 产 品 型 号 | D3: 产 品 名 称 | E3: 数量/件 | F3: 规格/KG | G3: 数量/KG | H3: 单价/元 | I3: 金额/元 | J3: 备 注 | L3: 贾总
A4: 46043 | D4: 808 | E4: 1 | F4: 120 | G4: =E4*F4 -> 120 | H4: 7.2 | I4: =G4*H4 -> 864 | L4: 邻居杨总
A5: 46043 | D5: 807A | E5: 1 | F5: 40 | G5: =E5*F5 -> 40 | H5: 6.1 | I5: =G5*H5 -> 244
A6: 46043 | D6: 白浆：自备 | E6: 1 | F6: 180 | G6: =E6*F6 -> 180
A7: 46043 | D7: 1#浆:35% | E7: 1 | F7: 200 | G7: =E7*F7 -> 200
A8: 46043 | D8: 3#浆：:17% | E8: 1 | F8: 230 | G8: =E8*F8 -> 230
A9: 46043 | D9: 108树脂：自备 | E9: 1 | F9: 230 | G9: =E9*F9 -> 230
A10: 46043 | D10: 亮白（普）加工费 | E10: 1 | F10: =SUM(F4:F9) -> 1000 | G10: =E10*F10 -> 1000 | H10: 1 | I10: =G10*H10 -> 1000
A16: 大 写 人 民 币 | D16: =I16 -> 2108 | I16: =SUM(I4:I15) -> 2108
A17: 销售协议 | B17: 1.甲方所供上列产品均属检验合格产品，乙方如有异议，应在收货七天内书面提出，逾期不提出视为质量合格。
B18: 2.乙方每次要认真核对产品的型号.名称.数量.规格.重量.单价.金额，经甲乙双方经手人（库管）签字后具有
C19: 法律效力，必须按期付清货款（月结三十天），如有争议和纠纷，由甲方所在地方人民法院受理起诉。
B20: 3.本送货单一式四联， 白色联为存根联， 粉红色为客户联， 蓝色联为结款联， 黄色联为会计联。
A21: 销售单位（甲方）：成都国圣工业有限公司 电话：028-85852618
A22: 销售负责人：李秋林 销售送货人： 销售制单人： 购货单位经手人： | M22: ①

Sheet 贾总出货
A1: 3月 | J1: 金额总计 | K1: =SUM(K11:K143) -> 49665.95 | L1: 李总材料金额 | M1: ='24材料明细'!AQ402 -> 36321.35 | N1: 加工费 | O1: =K15+K21+K31+K34+K43+K49+K55+K61+K68+K72+K76+K83+K90+K93+K102+K109+K117+K124+K131+K139+K143 -> 12001.1 | P1: 成品 | Q1: =K94+Q13 -> 310
J2: 加工吨位 | K2: =SUM(I15+I21+I31+I34+I43+I49+I55+I61+I68+I72+I76+I83+I90+I93+I102+I109+I117+I124+I131+I139+I143)/1000 -> 10.6233 | L2: 包装桶金额 | M2: =K16+K22+K28+K84+K95 -> 1033.5 | N2: 总金额 | O2: =M1+Q1+O1+M2 -> 49665.95
A3: 日期 | B3: 单号 | C3: 产品型号 | F3: 产品名称 | G3: 数量/件 | H3: 规格/KG | I3: 数量/KG | J3: 单价/元 | K3: 金额/元 | L3: 备注 | M3: 金额合计
A4: 45351 | B4: 待改材料未入账 | C4: 45351 | F4: 108树脂：自备（三木） | G4: 1 | H4: 60 | I4: =G4*H4 -> 60
A5: 45351 | B5: 待改材料未入账 | C5: 45351 | F5: 环己酮: | G5: 1 | H5: 60 | I5: =G5*H5 -> 60
A6: 45351 | B6: 待改材料未入账 | C6: 45351 | F6: 1/2":715浆：自备 | G6: 1 | H6: 10 | I6: =G6*H6 -> 10
A7: 45351 | B7: 待改材料未入账 | C7: 45351 | F7: 30"：730浆：自备 | G7: 1 | H7: 10 | I7: =G7*H7 -> 10
A8: 45351 | B8: 待改材料未入账 | C8: 45351 | F8: 仲丁酯 | G8: 1 | H8: 60 | I8: =G8*H8 -> 60
A9: 45351 | B9: 待改材料未入账 | C9: 45351 | F9: ABS光油加工费 | G9: 1 | H9: 200 | I9: =G9*H9 -> 200
A10: 45351 | B10: 待改材料未入账 | C10: 45351 | F10: 另加包装桶：20L | G10: 11 | H10: 1 | I10: =G10*H10 -> 11
A11: 45353 | B11: 7号 | C11: 45352 | F11: 108树脂：自备（三木） | G11: 1 | H11: 60 | I11: =G11*H11 -> 60
A12: 45353 | B12: 7号 | C12: 45352 | F12: 环己酮: | G12: 1 | H12: 42 | I12: =G12*H12 -> 42 | J12: 10.3 | K12: =I12*J12 -> 432.6
A13: 45353 | B13: 7号 | C13: 45352 | F13: 1/2":715浆：自备 | G13: 1 | H13: 34 | I13: =G13*H13 -> 34 | L13: ABS光油：11桶*17KG
A14: 45353 | B14: 7号 | C14: 45352 | F14: 30"：730浆：自备 | G14: 1 | H14: 64 | I14: =G14*H14 -> 64 | M14: 商标：ABS光油/重量：17±0.1KG
A15: 45353 | B15: 7号 | C15: 45352 | F15: ABS光油加工费 | G15: 1 | H15: 200 | I15: =G15*H15 -> 200 | J15: 1 | K15: =I15*J15 -> 200
A16: 45353 | B16: 7号 | C16: 45352 | F16: 另加包装桶：20L | G16: 11 | H16: 1 | I16: =G16*H16 -> 11 | J16: 13 | K16: =I16*J16 -> 143 | L16: =SUM(K11:K16) -> 775.6
A17: 45360 | B17: 24号 | C17: 45356 | F17: 甲缩醛 | G17: 1 | H17: 8 | I17: =G17*H17 -> 8 | J17: 3.4 | K17: =I17*J17 -> 27.2
A18: 45360 | B18: 24号 | C18: 45356 | F18: 粗甲酯 | G18: 1 | H18: 3 | I18: =G18*H18 -> 3 | J18: 3.6 | K18: =I18*J18 -> 10.8
A19: 45360 | B19: 24号 | C19: 45356 | F19: 仲丁酯 | G19: 1 | H19: 4 | I19: =G19*H19 -> 4 | J19: 6.3 | K19: =I19*J19 -> 25.2
A20: 45360 | B20: 24号 | C20: 45356 | F20: 环己酮 | G20: 1 | H20: 3 | I20: =G20*H20 -> 3 | J20: 10.3 | K20: =I20*J20 -> 30.9
A21: 45360 | B21: 24号 | C21: 45356 | F21: 稀料加工费 | G21: 1 | H21: 18 | I21: =G21*H21 -> 18 | J21: 0.7 | K21: =I21*J21 -> 12.6
A22: 45360 | B22: 24号 | C22: 45356 | F22: 另加包装桶：20L | G22: 1 | H22: 1 | I22: =G22*H22 -> 1 | J22: 13 | K22: =I22*J22 -> 13 | L22: =SUM(K17:K22) -> 119.7
A23: 45360 | B23: 25号 | C23: 45357 | F23: 自提：黑色浆自备 | G23: 1 | H23: 3 | I23: =G23*H23 -> 3
A24: 45360 | B24: 25号 | C24: 45357 | F24: 自提：红色浆自备 | G24: 1 | H24: 3 | I24: =G24*H24 -> 3
A25: 45360 | B25: 25号 | C25: 45358 | F25: 自提：715浆自备 | G25: 1 | H25: 3 | I25: =G25*H25 -> 3
A26: 45360 | B26: 25号 | C26: 45358 | F26: 自提：730浆自备 | G26: 1 | H26: 3 | I26: =G26*H26 -> 3
A27: 45360 | B27: 25号 | C27: 45358 | F27: 自提：7025银粉 | G27: 1 | H27: 2 | I27: =G27*H27 -> 2 | J27: 50 | K27: =I27*J27 -> 100
A28: 45360 | B28: 25号 | C28: 45358 | F28: 另加包装桶：4L | G28: 5 | H28: 1 | I28: =G28*H28 -> 5 | J28: 5.5 | K28: =I28*J28 -> 27.5 | L28: =SUM(K23:K28) -> 127.5
A29: 45360 | B29: 26号 | C29: 45357 | F29: 仲丁酯 | G29: 2 | H29: 60 | I29: =G29*H29 -> 120 | J29: 6.3 | K29: =I29*J29 -> 756
A30: 45360 | B30: 26号 | C30: 45357 | F30: 715粉：自备 | G30: 2 | H30: 25 | I30: =G30*H30 -> 50
A31: 45360 | B31: 26号 | C31: 45357 | F31: 715浆加工费 | G31: 2 | H31: 85 | I31: =G31*H31 -> 170 | J31: 0.8 | K31: =I31*J31 -> 136
A32: 45360 | B32: 26号 | C32: 45357 | F32: 仲丁酯 | G32: 2 | H32: 135 | I32: =G32*H32 -> 270 | J32: 6.3 | K32: =I32*J32 -> 1701
A33: 45360 | B33: 26号 | C33: 45357 | F33: 30秒：自备 | G33: 2 | H33: 25 | I33: =G33*H33 -> 50
A34: 45360 | B34: 26号 | C34: 45357 | F34: 730浆加工费 | G34: 2 | H34: 160 | I34: =G34*H34 -> 320 | J34: 0.8 | K34: =I34*J34 -> 256 | L34: =SUM(K29:K34) -> 2849
A35: 45360 | B35: 27号 | C35: 45358 | F35: 1206树脂：自备（15%） | G35: 1 | H35: 25.5 | I35: =G35*H35 -> 25.5
A36: 45360 | B36: 27号 | C36: 45358 | F36: 108树脂：自备夏总（3%） | G36: 1 | H36: 5 | I36: =G36*H36 -> 5
A37: 45360 | B37: 27号 | C37: 45358 | F37: C311浆：自备（15%） | G37: 1 | H37: 25.5 | I37: =G37*H37 -> 25.5
A38: 45360 | B38: 27号 | C38: 45358 | F38: 715浆：自备（7%） | G38: 1 | H38: 12 | I38: =G38*H38 -> 12
A39: 45360 | B39: 27号 | C39: 45358 | F39: 730浆：自备（26%） | G39: 1 | H39: 44 | I39: =G39*H39 -> 44
A40: 45360 | B40: 27号 | C40: 45358 | F40: 350哑粉：自备（0.8%） | G40: 1 | H40: 1.5 | I40: =G40*H40 -> 1.5
...

Sheet 25出货
A1: 2月 | B1: 25年2月起加工金额合计 | E1: =K1+K67+K291+K564+K712+K943+K1109+K1186+K1356+K1514 -> 490046.28 | F1: 25年2月加工费总计 | G1: =O1+O67+O291+O564+O712+O943+O1109+O1186+O1356+O1514 -> 167177.45 | J1: 金额总计 | K1: =SUM(K4:K65) -> 8954.284 | L1: 李总材料金额 | M1: =材料!L299 -> 4650.334 | N1: 加工费 | O1: =K11+K19+K26+K33+K38+K43+K51+K60+K65 -> 4237.55 | P1: 成品
J2: 加工吨位 | L2: 包装桶金额 | M2: =K27+K44 -> 64 | N2: 总金额 | O2: =M1+M2+O1+Q1 -> 8951.884
A3: 日期 | B3: 单号 | C3: 产品型号 | F3: 产品名称 | G3: 数量/件 | H3: 规格/KG | I3: 数量/KG | J3: 单价/元 | K3: 金额/元 | L3: 备注 | M3: 金额合计
A4: 45706 | B4: 13号 | C4: 45706 | F4: 108树脂：自备 | G4: 1 | H4: 99.5 | I4: =G4*H4 -> 99.5
A5: 45707 | B5: 13号 | C5: 45706 | F5: 1#浆 | G5: 1 | H5: 154.5 | I5: =G5*H5 -> 154.5
A6: 45707 | B6: 13号 | C6: 45706 | F6: 3#浆 | G6: 1 | H6: 39 | I6: =G6*H6 -> 39
A7: 45707 | B7: 13号 | C7: 45706 | F7: 中黄浆：自备 | G7: 1 | H7: 110 | I7: =G7*H7 -> 110 | L7: 18KG/桶
A8: 45707 | B8: 13号 | C8: 45706 | F8: 聚酮液：自备 | G8: 1 | H8: 55 | I8: =G8*H8 -> 55
A9: 45707 | B9: 13号 | C9: 45706 | F9: 808 | G9: 1 | H9: 28.5 | I9: =G9*H9 -> 28.5 | J9: 10 | K9: =I9*J9 -> 285
A10: 45707 | B10: 13号 | C10: 45706 | F10: 807+ | G10: 1 | H10: 65.5 | I10: =G10*H10 -> 65.5 | J10: 6.2 | K10: =I10*J10 -> 406.1
A11: 45707 | B11: 13号 | C11: 45706 | F11: ABS亮黄加工费 | G11: 1 | H11: =SUM(H4:H10) -> 552 | I11: =G11*H11 -> 552 | J11: 1 | K11: =I11*J11 -> 552 | L11: =SUM(K4:K11) -> 1243.1
A12: 45707 | B12: 14号 | C12: 45706 | F12: 108树脂：自备 | G12: 1 | H12: 90 | I12: =G12*H12 -> 90
A13: 45707 | B13: 14号 | C13: 45706 | F13: 5R大红浆：自备 | G13: 1 | H13: 90 | I13: =G13*H13 -> 90
A14: 45707 | B14: 14号 | C14: 45706 | F14: 3号浆：自备 | G14: 1 | H14: 128 | I14: =G14*H14 -> 128
A15: 45707 | B15: 14号 | C15: 45706 | F15: 808 | G15: 1 | H15: 60 | I15: =G15*H15 -> 60 | J15: 10 | K15: =I15*J15 -> 600 | L15: 17KG/桶（除白桶18KG*5桶）
A16: 45707 | B16: 14号 | C16: 45706 | F16: 807+ | G16: 1 | H16: 130 | I16: =G16*H16 -> 130 | J16: 6.2 | K16: =I16*J16 -> 806 | L16: =SUBTOTAL(9,#REF!) -> #REF!
A17: 45707 | B17: 14号 | C17: 45706 | F17: 807A | G17: 1 | H17: 12 | I17: =G17*H17 -> 12 | J17: 7.8 | K17: =I17*J17 -> 93.6
A18: 45707 | B18: 14号 | C18: 45706 | F18: 聚酮液 | G18: 1 | H18: 90 | I18: =G18*H18 -> 90
A19: 45707 | B19: 14号 | C19: 45706 | F19: 大红普加工费 | G19: 1 | H19: =SUM(H12:H18) -> 600 | I19: =G19*H19 -> 600 | J19: 1 | K19: =I19*J19 -> 600 | L19: =SUM(K12:K19) -> 2099.6
A20: 45710 | B20: 35号 | C20: 45709 | F20: 亮黄成品 | G20: 1 | H20: 673 | I20: =G20*H20 -> 673
A21: 45710 | B21: 35号 | C21: 45709 | F21: 6920防尘浆 | G21: 1 | H21: 3 | I21: =G21*H21 -> 3
A22: 45710 | B22: 35号 | C22: 45709 | F22: 106D | G22: 1 | H22: 20.5 | I22: =G22*H22 -> 20.5 | J22: 17 | K22: =I22*J22 -> 348.5 | M22: 加0.5
A23: 45710 | B23: 35号 | C23: 45709 | F23: 3000目重钙 | G23: 1 | H23: 65 | I23: =G23*H23 -> 65 | J23: 0.9 | K23: =I23*J23 -> 58.5 | L23: 18KG/桶 | M23: 加2.0
A24: 45710 | B24: 35号 | C24: 45709 | F24: 812+ | G24: 1 | H24: 4 | I24: =G24*H24 -> 4 | J24: 3.7 | K24: =I24*J24 -> 14.8 | M24: 加0.2
A25: 45710 | B25: 35号 | C25: 45709 | F25: 807+ | G25: 1 | H25: 4.5 | I25: =G25*H25 -> 4.5 | J25: 6.2 | K25: =I25*J25 -> 27.9
A26: 45710 | B26: 35号 | C26: 45709 | F26: 哑黄加工费 | G26: 1 | H26: =SUM(H20:H25) -> 770 | I26: =G26*H26 -> 770 | J26: 1 | K26: =I26*J26 -> 770
A27: 45710 | B27: 35号 | C27: 45709 | F27: 自提黑色浆包装 | G27: 4 | H27: 1 | I27: =G27*H27 -> 4 | J27: 12.5 | K27: =I27*J27 -> 50 | L27: =SUM(K20:K27) -> 1269.7
A28: 45710 | B28: 36号 | C28: 45710 | F28: 108树脂：自备 | G28: 1 | H28: 48 | I28: =G28*H28 -> 48
A29: 45710 | B29: 36号 | C29: 45710 | F29: 5014B:自备 | G29: 1 | H29: 4.5 | I29: =G29*H29 -> 4.5
A30: 45710 | B30: 36号 | C30: 45710 | F30: 996 | G30: 1 | H30: 150 | I30: =G30*H30 -> 150
A31: 45710 | B31: 36号 | C31: 45710 | F31: 807A | G31: 1 | H31: 30 | I31: =G31*H31 -> 30 | J31: 7.8 | K31: =I31*J31 -> 234
A32: 45710 | B32: 36号 | C32: 45710 | F32: 802A | G32: 1 | H32: 30 | I32: =G32*H32 -> 30 | J32: 7.8 | K32: =I32*J32 -> 234
A33: 45710 | B33: 36号 | C33: 45710 | F33: 白浆加工费 | G33: 1 | H33: =SUM(H28:H32) -> 262.5 | I33: =G33*H33 -> 262.5 | J33: 3 | K33: =I33*J33 -> 787.5 | L33: =SUM(K28:K33) -> 1255.5
A34: 45710 | B34: 37号 | C34: 45710 | F34: 108树脂：自备 | G34: 1 | H34: 24 | I34: =G34*H34 -> 24
A35: 45710 | B35: 37号 | C35: 45710 | F35: 996 | G35: 1 | H35: 75 | I35: =G35*H35 -> 75
A36: 45710 | B36: 37号 | C36: 45710 | F36: 807A | G36: 1 | H36: 15 | I36: =G36*H36 -> 15 | J36: 7.8 | K36: =I36*J36 -> 117
A37: 45710 | B37: 37号 | C37: 45710 | F37: 802A | G37: 1 | H37: 15 | I37: =G37*H37 -> 15 | J37: 7.8 | K37: =I37*J37 -> 117
A38: 45710 | B38: 37号 | C38: 45710 | F38: 白浆加工费 | G38: 1 | H38: =SUM(H34:H37) -> 129 | I38: =G38*H38 -> 129 | J38: 3 | K38: =I38*J38 -> 387 | L38: =SUM(K34:K38) -> 621
A39: 45712 | B39: 39号 | C39: 2月22、24 | F39: 108树脂：自备 | G39: 1 | H39: 50 | I39: =G39*H39 -> 50 | J39: 13.6
A40: 45712 | B40: 39号 | C40: 2月22、24 | F40: 5RK大红粉 | G40: 1 | H40: 25 | I40: =G40*H40 -> 25 | J40: 49 | L40: 23.2/KG
...

Sheet 材料
A1: 26年01月贾材料明细表 | G1: 李总材料金额合计 | L1: =F21+I21+L21+O21+R21+U21+X21+AA21+AD21+AG21+AJ21+AM21+AP21 -> 1561.4
A2: 日期 | B2: 摘要 | D2: 996钛白粉 | G2: 3000目 | J2: 106D、100C是红色字体 | M2: 7025浆：银粉 | P2: 20000分散 | S2: 8333:红色字体是已稀的 | V2: 防尘浆 | Y2: 808 | AB2: 807+ | AE2: 812+ | AH2: 816 | AK2: 802A | AN2: 807A
B3: 品名 | C3: 生产量/KG | D3: 数量 | E3: 单价 | F3: 金额 | G3: 数量 | H3: 单价 | I3: 金额 | J3: 数量 | K3: 单价 | L3: 金额 | M3: 数量 | N3: 单价 | O3: 金额 | P3: 数量 | Q3: 单价 | R3: 金额 | S3: 数量 | T3: 单价 | U3: 金额 | V3: 数量 | W3: 单价 | X3: 金额 | Y3: 数量 | Z3: 单价 | AA3: 金额 | AB3: 数量 | AC3: 单价 | AD3: 金额 | AE3: 数量 | AF3: 单价 | AG3: 金额 | AH3: 数量 | AI3: 单价 | AJ3: 金额 | AK3: 数量 | AL3: 单价 | AM3: 金额 | AN3: 数量 | AO3: 单价 | AP3: 金额
A4: 46025 | B4: 优特黑101A | C4: 1000 | Y4: 50 | Z4: 7.1 | AA4: =Y4*Z4 -> 355 | AK4: 124 | AL4: 6.1 | AM4: =AK4*AL4 -> 756.4 | AN4: 75 | AO4: 6 | AP4: =AN4*AO4 -> 450
C21: =SUM(C4:C20) -> 1000 | D21: =SUM(D4:D20) -> 0 | F21: =SUM(F4:F20) -> 0 | G21: =SUM(G4:G20) -> 0 | I21: =SUM(I4:I20) -> 0 | J21: =SUM(J4:J20) -> 0 | L21: =SUM(L4:L20) -> 0 | M21: =SUM(M4:M20) -> 0 | O21: =SUM(O4:O20) -> 0 | P21: =SUM(P4:P20) -> 0 | R21: =SUM(R4:R20) -> 0 | S21: =SUM(S4:S20) -> 0 | U21: =SUM(U4:U20) -> 0 | V21: =SUM(V4:V20) -> 0 | X21: =SUM(X4:X20) -> 0 | Y21: =SUM(Y4:Y20) -> 50 | AA21: =SUM(AA4:AA20) -> 355 | AB21: =SUM(AB4:AB20) -> 0 | AD21: =SUM(AD4:AD20) -> 0 | AE21: =SUM(AE4:AE20) -> 0 | AG21: =SUM(AG4:AG20) -> 0 | AH21: =SUM(AH4:AH20) -> 0 | AJ21: =SUM(AJ4:AJ20) -> 0 | AK21: =SUM(AK4:AK20) -> 124 | AM21: =SUM(AM4:AM20) -> 756.4 | AN21: =SUM(AN4:AN20) -> 75 | AP21: =SUM(AP4:AP20) -> 450
A23: 25年12月贾材料明细表 | G23: 李总材料金额合计 | L23: =F43+I43+L43+O43+R43+U43+X43+AA43+AD43+AG43+AJ43+AM43+AP43 -> 25383.25
A24: 日期 | B24: 摘要 | D24: 996钛白粉 | G24: 3000目 | J24: 106D、100C是红色字体 | M24: 7025浆：银粉 | P24: 20000分散 | S24: 8333:红色字体是已稀的 | V24: 防尘浆 | Y24: 808 | AB24: 807+ | AE24: 812+ | AH24: 816 | AK24: 802A | AN24: 807A
B25: 品名 | C25: 生产量/KG | D25: 数量 | E25: 单价 | F25: 金额 | G25: 数量 | H25: 单价 | I25: 金额 | J25: 数量 | K25: 单价 | L25: 金额 | M25: 数量 | N25: 单价 | O25: 金额 | P25: 数量 | Q25: 单价 | R25: 金额 | S25: 数量 | T25: 单价 | U25: 金额 | V25: 数量 | W25: 单价 | X25: 金额 | Y25: 数量 | Z25: 单价 | AA25: 金额 | AB25: 数量 | AC25: 单价 | AD25: 金额 | AE25: 数量 | AF25: 单价 | AG25: 金额 | AH25: 数量 | AI25: 单价 | AJ25: 金额 | AK25: 数量 | AL25: 单价 | AM25: 金额 | AN25: 数量 | AO25: 单价 | AP25: 金额
A26: 45993 | B26: 电镀大红 | C26: 200 | Y26: 40 | Z26: 7.5 | AA26: =Y26*Z26 -> 300 | AN26: 23 | AO26: 5.9 | AP26: =AN26*AO26 -> 135.7
A27: 45997 | B27: 优特黑101A | C27: 1000 | Y27: 50 | Z27: 7.5 | AA27: =Y27*Z27 -> 375 | AK27: 155 | AL27: 6.1 | AM27: =AK27*AL27 -> 945.5 | AN27: 95 | AO27: 5.9 | AP27: =AN27*AO27 -> 560.5 | AQ27: 125
A28: 46000 | B28: 中黄浆 | C28: 225 | Y28: 25 | Z28: 7.5 | AA28: =Y28*Z28 -> 187.5 | AN28: 25 | AO28: 5.9 | AP28: =AN28*AO28 -> 147.5 | AQ28: 98
A29: 46000 | B29: 亮黄 | C29: 502.5 | Y29: 26 | Z29: 7.5 | AA29: =Y29*Z29 -> 195 | AN29: 61 | AO29: 5.9 | AP29: =AN29*AO29 -> 359.9 | AQ29: 25
A30: 46001 | B30: C311黑色浆 | C30: 750 | P30: 25 | Q30: 82 | R30: =P30*Q30 -> 2050 | Y30: 300 | Z30: 7.5 | AA30: =Y30*Z30 -> 2250 | AB30: 125 | AC30: 5 | AD30: =AB30*AC30 -> 625 | AQ30: 50
A31: 46002 | B31: 优特黑101A | C31: 1000 | Y31: 50 | Z31: 7.5 | AA31: =Y31*Z31 -> 375 | AH31: 5 | AI31: 2.9 | AJ31: =AH31*AI31 -> 14.5 | AK31: 155 | AL31: 6.1 | AM31: =AK31*AL31 -> 945.5 | AN31: 95 | AO31: 5.9 | AP31: =AN31*AO31 -> 560.5 | AQ31: 79
A32: 46006 | B32: 亮大红 | C32: 500 | Y32: 50 | Z32: 7.5 | AA32: =Y32*Z32 -> 375 | AB32: 98 | AC32: 5 | AD32: =AB32*AC32 -> 490 | AN32: 20 | AO32: 5.9 | AP32: =AN32*AO32 -> 118 | AQ32: 1300
A33: 46014 | B33: 柠檬黄漆 | C33: 445 | Y33: 53 | Z33: 7.1 | AA33: =Y33*Z33 -> 376.3 | AB33: 25 | AC33: 5.1 | AD33: =AB33*AC33 -> 127.5 | AN33: 32 | AO33: 5.9 | AP33: =AN33*AO33 -> 188.8 | AQ33: 61
A34: 46014 | B34: 甲苯胺紫红浆 | C34: 172 | Y34: 45 | Z34: 7.1 | AA34: =Y34*Z34 -> 319.5 | AB34: 50 | AC34: 5.1 | AD34: =AB34*AC34 -> 255 | AQ34: 7
A35: 46014 | B35: 哑黄 | C35: 508 | J35: 12 | K35: 17 | L35: =J35*K35 -> 204 | V35: 2 | W35: 25 | X35: =V35*W35 -> 50 | AB35: 79 | AC35: 5.1 | AD35: =AB35*AC35 -> 402.9 | AE35: 55 | AF35: 3 | AG35: =AE35*AF35 -> 165 | AQ35: 45
A36: 46015 | B36: 730浆：17% | C36: 1918 | AB36: 1300 | AC36: 5.1 | AD36: =AB36*AC36 -> 6630 | AN36: 293 | AO36: 5.9 | AP36: =AN36*AO36 -> 1728.7
A37: 46381 | B37: 玫瑰红漆 | C37: 300 | Y37: 30 | Z37: 7.1 | AA37: =Y37*Z37 -> 213 | AB37: 61 | AC37: 5.1 | AD37: =AB37*AC37 -> 311.1 | AK37: 10 | AL37: 6.1 | AM37: =AK37*AL37 -> 61
A38: 46385 | B38: 酞蓝漆 | C38: 172 | Y38: 27 | Z38: 7.1 | AA38: =Y38*Z38 -> 191.7 | AB38: 7 | AC38: 5.1 | AD38: =AB38*AC38 -> 35.7 | AK38: 8 | AL38: 6.1 | AM38: =AK38*AL38 -> 48.8 | AN38: 13 | AO38: 6 | AP38: =AN38*AO38 -> 78
A39: 46386 | B39: 白浆 | C39: 258 | Y39: 30 | Z39: 7.1 | AA39: =Y39*Z39 -> 213 | AN39: 30 | AO39: 6 | AP39: =AN39*AO39 -> 180
A40: 46387 | B40: 哑白 | C40: 1002.5 | J40: 25 | K40: 17 | L40: =J40*K40 -> 425 | V40: 2.5 | W40: 25 | X40: =V40*W40 -> 62.5 | AB40: 45 | AC40: 5.1 | AD40: =AB40*AC40 -> 229.5 | AE40: 239 | AF40: 3 | AG40: =AE40*AF40 -> 717 | AK40: 85 | AL40: 6.2 | AM40: =AK40*AL40 -> 527 | AN40: 30 | AO40: 6 | AP40: =AN40*AO40 -> 180
A41: 46387 | B41: 白裂纹 | C41: 181.5 | J41: 10 | K41: 17 | L41: =J41*K41 -> 170 | AB41: 36.5 | AC41: 5.1 | AD41: =AB41*AC41 -> 186.15 | AE41: 32 | AF41: 3 | AG41: =AE41*AF41 -> 96
C43: =SUM(C26:C42) -> 9134.5 | D43: =SUM(D26:D42) -> 0 | F43: =SUM(F26:F42) -> 0 | G43: =SUM(G26:G42) -> 0 | I43: =SUM(I26:I42) -> 0 | J43: =SUM(J26:J42) -> 47 | L43: =SUM(L26:L42) -> 799 | M43: =SUM(M26:M42) -> 0 | O43: =SUM(O26:O42) -> 0 | P43: =SUM(P26:P42) -> 25 | R43: =SUM(R26:R42) -> 2050 | S43: =SUM(S26:S42) -> 0 | U43: =SUM(U26:U42) -> 0 | V43: =SUM(V26:V42) -> 4.5 | X43: =SUM(X26:X42) -> 112.5 | Y43: =SUM(Y26:Y42) -> 726 | AA43: =SUM(AA26:AA42) -> 5371 | AB43: =SUM(AB26:AB42) -> 1826.5 | AD43: =SUM(AD26:AD42) -> 9292.85 | AE43: =SUM(AE26:AE42) -> 326 | AG43: =SUM(AG26:AG42) -> 978 | AH43: =SUM(AH26:AH42) -> 5 | AJ43: =SUM(AJ26:AJ42) -> 14.5 | AK43: =SUM(AK26:AK42) -> 413 | AM43: =SUM(AM26:AM42) -> 2527.8 | AN43: =SUM(AN26:AN42) -> 717 | AP43: =SUM(AP26:AP42) -> 4237.6
A46: 25年11月贾材料明细表 | G46: 李总材料金额合计 | L46: =F68+I68+L68+O68+R68+U68+X68+AA68+AD68+AG68+AJ68+AM68+AP68 -> 38242.2
A47: 日期 | B47: 摘要 | D47: 996钛白粉 | G47: 3000目 | J47: 106D、100C是红色字体 | M47: 7025浆：银粉 | P47: 20000分散 | S47: 8333:红色字体是已稀的 | V47: 防尘浆 | Y47: 808 | AB47: 807+ | AE47: 812+ | AH47: 811 | AK47: 802A | AN47: 807A
B48: 品名 | C48: 生产量/KG | D48: 数量 | E48: 单价 | F48: 金额 | G48: 数量 | H48: 单价 | I48: 金额 | J48: 数量 | K48: 单价 | L48: 金额 | M48: 数量 | N48: 单价 | O48: 金额 | P48: 数量 | Q48: 单价 | R48: 金额 | S48: 数量 | T48: 单价 | U48: 金额 | V48: 数量 | W48: 单价 | X48: 金额 | Y48: 数量 | Z48: 单价 | AA48: 金额 | AB48: 数量 | AC48: 单价 | AD48: 金额 | AE48: 数量 | AF48: 单价 | AG48: 金额 | AH48: 数量 | AI48: 单价 | AJ48: 金额 | AK48: 数量 | AL48: 单价 | AM48: 金额 | AN48: 数量 | AO48: 单价 | AP48: 金额
A49: 45962 | B49: 亮黄 | C49: 502.5 | Y49: 26 | Z49: 7.6 | AA49: =Y49*Z49 -> 197.6 | AN49: 61 | AO49: 6.1 | AP49: =AN49*AO49 -> 372.1
A50: 45962 | B50: 亮大红 | C50: 500 | Y50: 50 | Z50: 7.6 | AA50: =Y50*Z50 -> 380 | AB50: 95 | AC50: 5.1 | AD50: =AB50*AC50 -> 484.5 | AN50: 10 | AO50: 6.1 | AP50: =AN50*AO50 -> 61
A51: 45966 | B51: 消光剂 | C51: 320 | J51: 40 | K51: 15 | L51: =J51*K51 -> 600 | AB51: 128 | AC51: 5.1 | AD51: =AB51*AC51 -> 652.8 | AK51: 146 | AL51: 6.2 | AM51: =AK51*AL51 -> 905.2
A52: 45967 | B52: 沈阳平光黑 | C52: 364.5 | J52: 8.6 | K52: 17 | L52: =J52*K52 -> 146.2 | V52: 1 | W52: 25 | X52: =V52*W52 -> 25 | Y52: 54 | Z52: 7.6 | AA52: =Y52*Z52 -> 410.4 | AE52: 34 | AF52: 3 | AG52: =AE52*AF52 -> 102 | AK52: 36 | AL52: 6.2 | AM52: =AK52*AL52 -> 223.2 | AN52: 45 | AO52: 6.1 | AP52: =AN52*AO52 -> 274.5
A53: 45969 | B53: 哑红 | C53: 500 | J53: 15 | K53: 17 | L53: =J53*K53 -> 255 | V53: 2 | W53: 25 | X53: =V53*W53 -> 50 | Y53: 47 | Z53: 7.6 | AA53: =Y53*Z53 -> 357.2 | AB53: 51 | AC53: 5.1 | AD53: =AB53*AC53 -> 260.1 | AE53: 30 | AF53: 3 | AG53: =AE53*AF53 -> 90 | AN53: 20 | AO53: 6.1 | AP53: =AN53*AO53 -> 122
A54: 45973 | B54: 黑色浆 | C54: 750 | P54: 25 | Q54: 82 | R54: =P54*Q54 -> 2050 | Y54: 300 | Z54: 7.6 | AA54: =Y54*Z54 -> 2280 | AB54: 125 | AC54: 5.1 | AD54: =AB54*AC54 -> 637.5
A55: 45974 | B55: 平光黑 | C55: 1006 | J55: 30 | K55: 17 | L55: =J55*K55 -> 510 | V55: 3 | W55: 25 | X55: =V55*W55 -> 75 | Y55: 150 | Z55: 7.6 | AA55: =Y55*Z55 -> 1140 | AE55: 75 | AF55: 3 | AG55: =AE55*AF55 -> 225 | AK55: 40 | AL55: 6.2 | AM55: =AK55*AL55 -> 248 | AN55: 117 | AO55: 6.1 | AP55: =AN55*AO55 -> 713.7
A56: 45975 | B56: 优特黑101A-1 | C56: 1000 | Y56: 102 | Z56: 7.6 | AA56: =Y56*Z56 -> 775.2 | AN56: 58 | AO56: 6.1 | AP56: =AN56*AO56 -> 353.8
A57: 45975 | B57: 优特黑101A | C57: 1000 | Y57: 50 | Z57: 7.6 | AA57: =Y57*Z57 -> 380 | AK57: 155 | AL57: 6.2 | AM57: =AK57*AL57 -> 961 | AN57: 95 | AO57: 6.1 | AP57: =AN57*AO57 -> 579.5
A58: 45976 | B58: 白浆 | C58: 344 | Y58: 40 | Z58: 7.6 | AA58: =Y58*Z58 -> 304 | AN58: 40 | AO58: 6.1 | AP58: =AN58*AO58 -> 244
A59: 45978 | B59: 哑白 | C59: 1002.5 | J59: 25 | K59: 17 | L59: =J59*K59 -> 425 | V59: 2.5 | W59: 25 | X59: =V59*W59 -> 62.5 | AB59: 59 | AC59: 5.1 | AD59: =AB59*AC59 -> 300.9 | AE59: 239 | AF59: 3 | AG59: =AE59*AF59 -> 717 | AK59: 30 | AL59: 6.2 | AM59: =AK59*AL59 -> 186 | AN59: 30 | AO59: 6.1 | AP59: =AN59*AO59 -> 183
A60: 45978 | B60: 亮白 | C60: 1200 | Y60: 144 | Z60: 7.6 | AA60: =Y60*Z60 -> 1094.4 | AN60: 186 | AO60: 6.1 | AP60: =AN60*AO60 -> 1134.6
...

Sheet 回款
A1: 2026年1月贾总回款
A2: 日 期 | B2: 应付款合计金额/元 | E2: 已付款合计金额/元 | F2: 下欠款合计金额/元 | G2: 备 注
B3: =SUM(D7:D34) -> 39250.8 | E3: =SUM(E7:E34) -> 84745 | F3: =B3-E3 -> -45494.2
B5: 明细如下：
B6: 随机单号 | C6: 内容摘要 | D6: 金额 | E6: 已付款金额 | F6: 下欠款金额结存
A7: 11月 | C7: 结存 | E7: 57378 | F7: =D7-E7 -> -57378
A8: 46024 | B8: 2 | C8: 亮光固化剂、包装 | D8: 1885 | F8: =F7+D8-E8 -> -55493
A9: 46025 | B9: 8 | C9: 优特黑101A | D9: 2561.4 | F9: =F8+D9-E9 -> -52931.6
A10: 46031 | C10: 购996钛白粉:14200 | D10: 14200 | F10: =F9+D10-E10 -> -38731.6
A11: 46032 | B11: 22 | C11: 白浆 | D11: 1556 | F11: =F10+D11-E11 -> -37175.6
A12: 46032 | B12: 28 | C12: 桃红 | D12: 250.2 | F12: =F11+D12-E12 -> -36925.4
A13: 46032 | B13: 29 | C13: ABS光油 | D13: 1611.8 | F13: =F12+D13-E13 -> -35313.6
A14: 46036 | C14: 国圣购1/2浆：144KG*16.8=756 | E14: 2419 | F14: =F13+D14-E14 -> -37732.6
A15: 46035 | B15: 36 | C15: 亮白 | D15: 2296 | F15: =F14+D15-E15 -> -35436.6
A16: 46038 | B16: 44 | C16: 亮大红 | D16: 1423 | F16: =F15+D16-E16 -> -34013.6
A17: 46038 | C17: 蓉渝达原材料（预支款） | E17: 24948 | F17: =F16+D17-E17 -> -58961.6
A18: 46041 | B18: 50 | C18: 730#浆 | D18: 6178 | F18: =F17+D18-E18 -> -52783.6
A19: 46043 | B19: 58号 | C19: 平光黑 | D19: 3634 | F19: =F18+D19-E19 -> -49149.6
A20: 46044 | B20: 61 | C20: 沈阳平光黑 | D20: 1547.4 | F20: =F19+D20-E20 -> -47602.2
A21: 46044 | B21: 62 | C21: 亮白 | D21: 2108 | F21: =F20+D21-E21 -> -45494.2
F22: =F21+D22-E22 -> -45494.2
F23: =F22+D23-E23 -> -45494.2
F24: =F23+D24-E24 -> -45494.2
F25: =F24+D25-E25 -> -45494.2
F26: =F25+D26-E26 -> -45494.2
F27: =F26+D27-E27 -> -45494.2
F28: =F27+D28-E28 -> -45494.2
F29: =F28+D29-E29 -> -45494.2
F30: =F29+D30-E30 -> -45494.2
F31: =F30+D31-E31 -> -45494.2
F32: =F31+D32-E32 -> -45494.2
F33: =F32+D33-E33 -> -45494.2
A35: 贾总购钛白粉明细如下：
A36: 日 期 | C36: 内容摘要 | D36: 件数/包 | E36: 数量/KG（规格：25KG/件） | F36: 备注
A37: 2025.12.31 | C37: 贾总结存钛白粉 | E37: 50
A38: 2026.01.09 | C38: 购996钛白粉1吨:14200(未付款） | E38: 1000
A39: 2026.01.10 | C39: 磨白浆1.5槽用钛白粉 | E39: -200
A44: 截止2025年12月30日贾总结存钛白粉数量/KG | E44: =SUM(E37:E43) -> 850
A46: 2025年12月贾总回款
A47: 日 期 | B47: 应付款合计金额/元 | E47: 已付款合计金额/元 | F47: 下欠款合计金额/元 | G47: 备 注
...

Sheet 代号明细
A1: 贾总2024.12.25
A2: 产品代号 | B2: 名称 | C2: 规格/KG | E2: 产品代号 | F2: 名称 | G2: 规格
A3: 101A | B3: 优特黑 | C3: 17 | E3: 115 | F3: 橙 红 | G3: 17
A4: 101 | B4: 烤漆黑 | C4: 17 | E4: 116 | F4: 桃 红 | G4: 17
A5: 102 | B5: 平光黑 | C5: 17 | E5: 117 | F5: 艳 红 | G5: 17
A6: 103 | B6: 亮 白 | C6: 18 | E6: 118 | F6: 玫瑰红 | G6: 17
A7: 104 | B7: 哑 白 | C7: 18 | E7: 119 | F7: 白裂纹 | G7: 17
A8: 105 | B8: 亮大红 | C8: 17 | E8: 120 | F8: 黑裂纹 | G8: 17
A9: 106 | B9: 哑大红 | C9: 18 | E9: 121 | F9: 弹性漆 | G9: 17
A10: 107 | B10: 亮 黄 | C10: 18 | E10: 122 | F10: 电镀亮白 | G10: 17
A11: 108 | B11: 哑 黄 | C11: 18 | E11: 123 | F11: 电镀中黄 | G11: 18
A12: 109 | B12: 印花精油 | E12: 124 | F12: 电镀大红 | G12: 17
A13: 110 | B13: ABS光油 | C13: 17 | E13: 125 | F13: 电镀黑亮光 | G13: 17
A14: 111 | B14: 酞蓝漆 | C14: 17 | E14: 126 | F14: 电镀黑半光 | G14: 17
A15: 112 | B15: 柠檬黄 | C15: 18 | E15: 127 | F15: 橡皮漆底黑 | G15: 17
A16: 113 | B16: 绿 色 | E16: 128 | F16: 烤漆亮光精油 | G16: 18
A17: 114 | B17: 消光剂 | C17: 16 | E17: 129 | F17: 橡皮漆黑亮光 | G17: 17
E18: 130 | F18: 环保亮黄 | G18: 18
E19: 131 | F19: 环保哑黄 | G19: 18
A21: 11月11日前购的11桶中3#是25%
A22: 11月11 | B22: 购1#浆35% | C22: 200*6*16.5=19800
A23: 11月11 | B23: 购3#浆20% | C23: 190*5桶*13.2=12540

Sheet 24材料明细
A1: 24年12月贾2材料明细表 | T1: 715、730浆含贾总自提的2桶和以前自提均未减账 | AL1: 李总材料金额合计 | AQ1: =AK46+AN46+AQ46+AT46+AW46+AZ46+BC46+BF46+BI46+BL46+BO46+BR46+BU46 -> 36675.878
A2: 日期 | B2: 摘要 | D2: 艳红浆 | E2: 聚酮液 | F2: 甲胺紫浆 | G2: 1206树脂 | H2: 108树脂未统计购货 | I2: 白浆 | J2: 5R大红浆 | K2: 31/8:5R大红浆 | L2: 酞青蓝浆 | M2: 柠檬黄浆 | N2: 橙红浆 | O2: 中黄浆 | P2: C311黑浆 | Q2: 平光黑浆半成品 | R2: 平光黑浆成品 | S2: 7900-2x防尘浆 | T2: 715浆 | U2: 730浆 | V2: 桃红浆 | W2: 5014 | X2: 5050分散剂 | Y2: 120浆 | Z2: 中黄色粉 | AA2: 715粉 | AB2: 730粉 | AC2: 350粉 | AD2: 520粉 | AE2: 橙黄粉 | AF2: C311粉 | AG2: 5RK粉 | AH2: 日期 | AI2: 996钛白粉 | AL2: 3000目 | AO2: 106D、100C是红色字体 | AR2: 7025浆：银粉 | AU2: 20000分散 | AX2: 6920浆 | BA2: 4010助 | BD2: 808 | BG2: 807+ | BJ2: 812+ | BM2: 811 | BP2: 802A | BS2: 807A
B3: 品名 | C3: 生产量/KG | AI3: 数量 | AJ3: 单价 | AK3: 金额 | AL3: 数量 | AM3: 单价 | AN3: 金额 | AO3: 数量 | AP3: 单价 | AQ3: 金额 | AR3: 数量 | AS3: 单价 | AT3: 金额 | AU3: 数量 | AV3: 单价 | AW3: 金额 | AX3: 数量 | AY3: 单价 | AZ3: 金额 | BA3: 数量 | BB3: 单价 | BC3: 金额 | BD3: 数量 | BE3: 单价 | BF3: 金额 | BG3: 数量 | BH3: 单价 | BI3: 金额 | BJ3: 数量 | BK3: 单价 | BL3: 金额 | BM3: 数量 | BN3: 单价 | BO3: 金额 | BP3: 数量 | BQ3: 单价 | BR3: 金额 | BS3: 数量 | BT3: 单价 | BU3: 金额
A4: 11月30 | B4: 30/11结存 | D4: =D54 -> 0 | E4: =E79 -> 587 | F4: =F79 -> 175 | G4: =G79 -> 0 | H4: =H79 -> 0 | I4: =I79 -> 480 | J4: =J79 -> 536 | K4: =K79 -> 0 | L4: =L79 -> -15 | ... AG4: =AG79 -> 0
A5: 12月5 | B5: 亮大红（108：75KG、3号浆107未入库） | C5: 500 | E5: -75 | J5: -75 | AH5: 45631 | BD5: 50 | BE5: 10.5 | BF5: =BD5*BE5 -> 525 | BG5: 118 | BH5: 5.9 | BI5: =BG5*BH5 -> 696.2
A6: 45631 | B6: 桃红漆（桃红浆100KG，树脂75,1号浆52、3号浆73未入库） | C6: 500 | E6: -63 | AH6: 45631 | BD6: 62 | BE6: 10.5 | BF6: =BD6*BE6 -> 651 | BG6: 75 | BH6: 5.9 | BI6: =BG6*BH6 -> 442.5
A7: 45632 | B7: 电镀黑亮光（1206:100、108:12、1号浆21、3号浆：58未入库） | C7: 400 | P7: -60 | AH7: 45632 | BD7: 80 | BE7: 10.5 | BF7: =BD7*BE7 -> 840 | BG7: 69 | BH7: 5.9 | BI7: =BG7*BH7 -> 407.1
A8: 45635 | B8: 烤漆黑（树脂200、1号浆：51、3号浆：214未入库） | C8: 1000 | P8: -150 | AH8: 45635 | BD8: 200 | BE8: 10.5 | BF8: =BD8*BE8 -> 2100 | BG8: 60 | BH8: 5.9 | BI8: =BG8*BH8 -> 354 | BP8: 125 | BQ8: 7.2 | BR8: =BP8*BQ8 -> 900
A9: 45635 | B9: 优特黑（108树脂150、1号浆147、3号浆253未入库） | C9: 1000 | P9: -150 | AH9: 45635 | BD9: 50 | BE9: 10.5 | BF9: =BD9*BE9 -> 525 | BG9: 96 | BH9: 5.9 | BI9: =BG9*BH9 -> 566.4 | BP9: 154 | BQ9: 7.2 | BR9: =BP9*BQ9 -> 1108.8
A10: 45636 | B10: 橡皮漆底黑（二元氯醋：100未入库） | C10: 480 | P10: -84 | AH10: 45636 | AO10: 22 | AP10: 17 | AQ10: =AO10*AP10 -> 374 | BD10: 80 | BE10: 10.5 | BF10: =BD10*BE10 -> 840 | BG10: 94 | BH10: 5.9 | BI10: =BG10*BH10 -> 554.6 | BJ10: 60 | BK10: 3.6 | BL10: =BJ10*BK10 -> 216 | BP10: 40 | BQ10: 6.8 | BR10: =BP10*BQ10 -> 272
A11: 45638 | B11: 中黄浆（中黄粉：25KG,108:10未入库 | C11: 45 | AH11: 45638 | BD11: 5 | BE11: 9.3 | BF11: =BD11*BE11 -> 46.5 | BS11: 5 | BT11: 7.8 | BU11: =BS11*BT11 -> 39
A12: 45638 | B12: 入库中黄浆：15%的损耗 | O12: 38 | AH12: 45638
A13: 45639 | B13: 优特黑（108树脂150、1号浆147、3号浆253未入库） | C13: 1000 | P13: -150 | AH13: 45635 | BD13: 50 | BE13: 9.3 | BF13: =BD13*BE13 -> 465 | BG13: 95 | BH13: 5.9 | BI13: =BG13*BH13 -> 560.5 | BP13: 155 | BQ13: 6.8 | BR13: =BP13*BQ13 -> 1054
A14: 45640 | B14: 白浆（树脂：96KG,5014B:9KG未入库） | C14: 525 | AH14: 45640 | AI14: 300 | BP14: 60 | BQ14: 6.8 | BR14: =BP14*BQ14 -> 408 | BS14: 60 | BT14: 7.8 | BU14: =BS14*BT14 -> 468
A15: 45640 | B15: 入库白浆（2%损耗） | I15: 514 | AH15: 45640
A16: 45640 | B16: 柠檬黄漆（108树脂：58、柠檬浆63、1#浆26、3#浆：37未入库 | C16: 252 | AH16: 45640 | BD16: 30 | BE16: 9.3 | BF16: =BD16*BE16 -> 279 | BG16: 38 | BH16: 5.9 | BI16: =BG16*BH16 -> 224.2
A17: 45643 | B17: 亮白普（108：200KG、外购715:51KG、外购730:214KG未入库） | C17: 1000 | E17: -125 | I17: -200 | AH17: 45643 | BD17: 25 | BE17: 9.3 | BF17: =BD17*BE17 -> 232.5 | BG17: 135 | BH17: 5.9 | BI17: =BG17*BH17 -> 796.5 | BP17: 50 | BQ17: 6.8 | BR17: =BP17*BQ17 -> 340
A18: 45644 | B18: 玫瑰红漆（树脂45KG、3号浆64未入库） | C18: 300 | E18: -45 | F18: -45 | AH18: 45644 | BD18: 30 | BE18: 9.3 | BF18: =BD18*BE18 -> 279 | BG18: 61 | BH18: 5.9 | BI18: =BG18*BH18 -> 359.9 | BP18: 10 | BQ18: 6.8 | BR18: =BP18*BQ18 -> 68
A19: 45644 | B19: 哑白普(108:100，色片白100、白浆100、715浆136、防尘浆2.5） | C19: 1052.5 | Y19: -260 | AH19: 45644 | AL19: 50 | AM19: 0.9 | AN19: =AL19*AM19 -> 45 | AO19: 25 | AP19: 17 | AQ19: =AO19*AP19 -> 425 | BJ19: 279 | BK19: 3.6 | BL19: =BJ19*BK19 -> 1004.4
A20: 45644 | B20: 亮黄漆（108:6.48,1#浆：10.08,3#浆：2.52，黄浆：7.2 | C20: 36 | E20: -3.6 | AH20: 45644 | BD20: 1.8 | BE20: 9.3 | BF20: =BD20*BE20 -> 16.74 | BG20: 4.32 | BH20: 5.9 | BI20: =BG20*BH20 -> 25.488
A21: 45646 | B21: ABS光油（108:150,1/4浆（715）：85 730浆：160 | C21: 500 | AH21: 45646 | BD21: 105 | BE21: 9.3 | BF21: =BD21*BE21 -> 976.5
A22: 45646 | B22: 哑红（树脂：50KG，1/4）：70,，防尘浆：2，改亮大红：53未入库） | C22: 606 | J22: -75 | Y22: -130 | AH22: 45646 | AL22: 50 | AM22: 0.9 | AN22: =AL22*AM22 -> 45 | AO22: 16 | AP22: 17 | AQ22: =AO22*AP22 -> 272 | BG22: 30 | BH22: 5.9 | BI22: =BG22*BH22 -> 177 | BJ22: 130 | BK22: 3.6 | BL22: =BJ22*BK22 -> 468
A23: 12月20-21 | B23: C311黑浆（色粉：100KG,树脂200KG未计入库存） | C23: 750 | AH23: 12-20-21 | AU23: 25 | AV23: 75 | AW23: =AU23*AV23 -> 1875 | BD23: 300 | BE23: 9.3 | BF23: =BD23*BE23 -> 2790 | BG23: 125 | BH23: 5.9 | BI23: =BG23*BH23 -> 737.5
A24: 45647 | B24: 入库黑色浆 | P24: 735 | AH24: 45647
A25: 45647 | B25: 亮白普（108180KG、外购715:46KG、外购730:193KG未入库） | C25: 900 | E25: -112 | I25: -180 | AH25: 45647 | BD25: 23 | BE25: 9.3 | BF25: =BD25*BE25 -> 213.9 | BG25: 121 | BH25: 5.9 | BI25: =BG25*BH25 -> 713.9 | BP25: 45 | BQ25: 6.8 | BR25: =BP25*BQ25 -> 306
A26: 45647 | B26: 烤漆黑（树脂200、1号浆：51、3号浆：214未入库） | C26: 1000 | P26: -150 | AH26: 45647 | BD26: 200 | BE26: 9.3 | BF26: =BD26*BE26 -> 1860 | BG26: 60 | BH26: 5.9 | BI26: =BG26*BH26 -> 354 | BP26: 125 | BQ26: 6.8 | BR26: =BP26*BQ26 -> 850
A27: 45649 | B27: 亮黄（树脂27，1号浆：,421、3号浆：10.5未入库 | C27: 150 | E27: -15 | N27: -30 | AH27: 45649 | BD27: 7.5 | BE27: 9.3 | BF27: =BD27*BE27 -> 69.75 | BG27: 18 | BH27: 5.9 | BI27: =BG27*BH27 -> 106.2
A28: 45650 | B28: 亮大红（108：90KG、3号浆128未入库） | C28: 600 | E28: -90 | J28: -90 | AH28: 45650 | BD28: 60 | BE28: 9.3 | BF28: =BD28*BE28 -> 558 | BG28: 142 | BH28: 5.9 | BI28: =BG28*BH28 -> 837.8
A29: 45650 | B29: 平光黑（树脂150、3#浆145、6920；3未入库） | C29: 1003 | P29: -120 | T29: -140 | AH29: 45650 | AO29: 30 | AP29: 17 | AQ29: =AO29*AP29 -> 510 | BD29: 100 | BE29: 9.3 | BF29: =BD29*BE29 -> 930 | BG29: 40 | BH29: 5.9 | BI29: =BG29*BH29 -> 236 | BJ29: 200 | BK29: 3.6 | BL29: =BJ29*BK29 -> 720 | BP29: 75 | BQ29: 6.8 | BR29: =BP29*BQ29 -> 510
A30: 45651 | B30: 消光剂（树脂：3） | C30: 160 | AH30: 45651 | AO30: 20 | AP30: 15 | AQ30: =AO30*AP30 -> 300 | BG30: 64 | BH30: 5.9 | BI30: =BG30*BH30 -> 377.6 | BP30: 73 | BQ30: 6.8 | BR30: =BP30*BQ30 -> 496.4
A31: 45657 | B31: 白浆（树脂：96KG,5014B:9KG未入库） | C31: 525 | AH31: 45657 | AI31: 300 | BP31: 60 | BQ31: 6.8 | BR31: =BP31*BQ31 -> 408 | BS31: 60 | BT31: 7.8 | BU31: =BS31*BT31 -> 468
A32: 45657 | B32: 入库白浆（2%损耗） | I32: 514 | AH32: 45657
C46: =SUM(C5:C45) -> 14284.5 | D46: =SUM(D5:D26) -> 0 | E46: =SUM(E4:E45) -> 58.4 | F46: =SUM(F4:F45) -> 130 | G46: =SUM(G4:G45) -> 0 | H46: =SUM(H4:H45) -> 0 | I46: =SUM(I4:I45) -> 1128 | J46: =SUM(J4:J45) -> 296 | K46: =SUM(K4:K45) -> 0 | L46: =SUM(L4:L45) -> -15 | ... AG46: =SUM(AG4:AG45) -> 0 | AI46: =SUM(AI4:AI45) -> 600 | AK46: =SUM(AK4:AK45) -> 0 | AL46: =SUM(AL4:AL45) -> 100 | AN46: =SUM(AN4:AN45) -> 90 | AO46: =SUM(AO4:AO45) -> 113 | AQ46: =SUM(AQ4:AQ45) -> 1881 | AR46: =SUM(AR4:AR45) -> 0 | AT46: =SUM(AT4:AT45) -> 0 | AU46: =SUM(AU4:AU45) -> 25 | AW46: =SUM(AW4:AW45) -> 1875 | AX46: =SUM(AX4:AX45) -> 0 | AZ46: =SUM(AZ4:AZ45) -> 0 | BA46: =SUM(BA4:BA45) -> 0 | BC46: =SUM(BC4:BC45) -> 0 | BD46: =SUM(BD4:BD45) -> 1459.3 | BF46: =SUM(BF4:BF45) -> 14197.89 | BG46: =SUM(BG4:BG45) -> 1445.32 | BI46: =SUM(BI4:BI45) -> 8527.388 | BJ46: =SUM(BJ4:BJ45) -> 669 | BL46: =SUM(BL4:BL45) -> 2408.4 | BM46: =SUM(BM4:BM45) -> 0 | BO46: 0 | BP46: =SUM(BP4:BP45) -> 972 | BR46: =SUM(BR4:BR45) -> 6721.2 | BS46: =SUM(BS4:BS45) -> 125 | BU46: =SUM(BU4:BU45) -> 975
A51: 24年10月贾总材料明细表 | T51: 715、730浆含贾总自提的2桶和以前自提均未减账 | AL51: 李总材料金额合计 | AQ51: =AK79+AN79+AQ79+AT79+AW79+AZ79+BC79+BF79+BI79+BL79+BO79+BR79+BU79 -> 33968.92
A52: 日期 | B52: 摘要 | D52: 艳红浆 | E52: 聚酮液 | F52: 甲胺紫浆 | G52: 1206树脂 | H52: 108树脂未统计购货 | I52: 白浆 | J52: 5R大红浆 | K52: 31/8:5R大红浆 | L52: 酞青蓝浆 | M52: 柠檬黄浆 | N52: 橙红浆 | O52: 中黄浆 | P52: C311黑浆 | Q52: 平光黑浆半成品 | R52: 平光黑浆成品 | S52: 7900-2x防尘浆 | T52: 715浆 | U52: 730浆 | V52: 桃红浆 | W52: 5014 | X52: 5050分散剂 | Y52: 120浆 | Z52: 中黄色粉 | AA52: 715粉 | AB52: 730粉 | AC52: 350粉 | AD52: 520粉 | AE52: 橙黄粉 | AF52: C311粉 | AG52: 5RK粉 | AH52: 日期 | AI52: 996钛白粉 | AL52: 3000目 | AO52: 106D、100C是红色字体 | AR52: 7025浆：银粉 | AU52: 20000分散 | AX52: 6920浆 | BA52: 4010助 | BD52: 808 | BG52: 807+ | BJ52: 812+ | BM52: 811 | BP52: 802A | BS52: 807A
B53: 品名 | C53: 生产量/KG | AI53: 数量 | AJ53: 单价 | AK53: 金额 | AL53: 数量 | AM53: 单价 | AN53: 金额 | AO53: 数量 | AP53: 单价 | AQ53: 金额 | AR53: 数量 | AS53: 单价 | AT53: 金额 | AU53: 数量 | AV53: 单价 | AW53: 金额 | AX53: 数量 | AY53: 单价 | AZ53: 金额 | BA53: 数量 | BB53: 单价 | BC53: 金额 | BD53: 数量 | BE53: 单价 | BF53: 金额 | BG53: 数量 | BH53: 单价 | BI53: 金额 | BJ53: 数量 | BK53: 单价 | BL53: 金额 | BM53: 数量 | BN53: 单价 | BO53: 金额 | BP53: 数量 | BQ53: 单价 | BR53: 金额 | BS53: 数量 | BT53: 单价 | BU53: 金额
A54: 10月 | B54: 31/10结存 | D54: =D130 -> 0 | E54: =E130 -> 382 | F54: =F130 -> 175 | G54: =G130 -> 0 | H54: =H130 -> 0 | I54: =I130 -> 666 | J54: =J130 -> 611 | K54: =K130 -> 0 | ... AG54: =AG130 -> 0
A55: 45597 | B55: 白浆（树脂：48KG,5014B:4.5KG未入库） | C55: 262.5 | AH55: 45597 | AI55: 150 | BP55: 30 | BQ55: 7.2 | BR55: =BP55*BQ55 -> 216 | BS55: 30 | BT55: 7.5 | BU55: =BS55*BT55 -> 225
A56: 45597 | B56: 入库白浆（2%损耗） | I56: 257 | AH56: 45597
A57: 45603 | B57: 亮白普（108：200KG、外购715:51KG、外购730:214KG未入库） | C57: 1000 | E57: -125 | I57: -200 | AH57: 45603 | BD57: 25 | BE57: 10.6 | BF57: =BD57*BE57 -> 265 | BG57: 78 | BH57: 6.3 | BI57: =BG57*BH57 -> 491.4 | BP57: 107 | BQ57: 7.2 | BR57: =BP57*BQ57 -> 770.4
...

Sheet 贾总购原材料
A1: 23年10月23日起贾总购货明细
A2: 日期 | B2: 客户名 | C2: 品名 | D2: 件数/桶 | E2: 规格/KG | F2: 数量/KG | G2: 单价/元 | H2: 金额/元 | I2: 备注
A3: 10-23日 | B3: 金银岛 | C3: 二甲苯 | D3: 6 | E3: 175 | F3: =E3*D3 -> 1050 | G3: 8.6 | H3: =F3*G3 -> 9030
A4: 10-23日 | B4: 金银岛 | C4: 环己酮 | D4: 6 | E4: 180 | F4: =E4*D4 -> 1080 | G4: 10.8 | H4: =F4*G4 -> 11664
A5: 10-23日 | B5: 金银岛 | C5: 仲丁酯 | D5: 5 | E5: 180 | F5: =E5*D5 -> 900 | G5: 7.2 | H5: =F5*G5 -> 6480 | I5: 溶剂购货单贾总于24/10日已提
A6: 10-23日 | B6: 金银岛 | C6: 粗甲酯 | D6: 4 | E6: 180 | F6: =E6*D6 -> 720 | G6: 4.2 | H6: =F6*G6 -> 3024
A7: 10-23日 | B7: 金银岛 | C7: 丁酯 | D7: 3 | E7: 180 | F7: =E7*D7 -> 540 | G7: 9.5 | H7: =F7*G7 -> 5130 | I7: =SUM(H3:H7) -> 35328
A8: 45223 | B8: 入库 | C8: 1160黑色浆 | D8: 3 | E8: 20 | F8: =E8*D8 -> 60 | I8: 无购货单：贾、李总经手
A9: 45223 | B9: 入库 | C9: 108树脂 | D9: 5 | E9: 190 | F9: =E9*D9 -> 950 | I9: 无购货单：贾、李总经手
A10: 45223 | B10: 入库 | C10: 730浆 | D10: 1 | E10: 1 | F10: 1120 | I10: 无购货单：贾、李总经手
A11: 45223 | B11: 入库 | C11: 715浆 | D11: 1 | E11: 1 | F11: 680 | I11: 无购货单：贾、李总经手
A12: 45228 | B12: 托运部送 | C12: 酞青蓝色粉 | D12: 2 | E12: 25 | F12: =E12*D12 -> 50 | I12: 无购货单：李总经手
A13: 45228 | B13: 托运部送 | C13: 托运费：李总付 | D13: 1 | E13: 1 | F13: 13 | I13: 无购货单：李总经手
A14: 45234 | B14: 送货未给单 | C14: 购30" | D14: 8 | E14: 25 | F14: =E14*D14 -> 200 | I14: 无购货单：李总经手
A15: 24购材料
A17: 45348 | B17: 赵永平 | C17: R369钛白粉 | D17: 80 | E17: 25 | F17: =E17*D17 -> 2000 | G17: 16.6 | H17: =F17*G17 -> 33200 | I17: =H17 -> 33200
A18: 45357 | B18: 715粉 | C18: 715粉 | D18: 2 | E18: 25 | F18: =E18*D18 -> 50 | G18: 28 | H18: =F18*G18 -> 1400
A19: 45357 | B19: 730粉 | C19: 730粉 | D19: 2 | E19: 25 | F19: =E19*D19 -> 50 | G19: 28 | H19: =F19*G19 -> 1400 | I19: =SUM(H18:H19) -> 2800
A20: 45357 | B20: 入库：贾总带来 | C20: 1206树脂 | D20: 1 | E20: 190 | F20: =E20*D20 -> 190
A21: 45369 | B21: 文萱：长圣 | C21: 5014分散剂 | D21: 1 | E21: 25 | F21: =E21*D21 -> 25 | G21: 56 | H21: =F21*G21 -> 1400
A22: 45369 | B22: 文萱：长圣 | C22: 5050分散剂 | D22: 1 | E22: 25 | F22: =E22*D22 -> 25 | G22: 56 | H22: =F22*G22 -> 1400
A23: 45369 | B23: 文萱：长圣 | C23: 7900-20X防尘浆 | D23: 3 | E23: 16 | F23: =E23*D23 -> 48 | G23: 38 | H23: =F23*G23 -> 1824 | I23: =SUM(H21:H23) -> 4624 | J23: 田如海：028-83989981
A24: 45371 | B24: 余氏东风 | C24: 酞青蓝粉 | D24: 2 | E24: 25 | F24: =E24*D24 -> 50 | H24: =F24*G24 -> 0 | I24: 无货单
A25: 45371 | B25: 余氏东风 | C25: 购中络黄粉 | D25: 4 | E25: 25 | F25: =E25*D25 -> 100 | H25: =F25*G25 -> 0 | I25: 无货单
A26: 45371 | B26: 余氏东风 | C26: 托运费：李总付:37 | D26: 6 | E26: 1 | F26: =E26*D26 -> 6 | G26: 6.17 | H26: 37
A27: 45357 | B27: 715粉 | C27: 715粉 | D27: 12 | E27: 25 | F27: =E27*D27 -> 300 | G27: 26 | H27: =F27*G27 -> 7800
A28: 45357 | B28: 730粉 | C28: 730粉 | D28: 8 | E28: 25 | F28: =E28*D28 -> 200 | G28: 26 | H28: =F28*G28 -> 5200 | I28: =SUM(H27:H28) -> 13000 | J28: 无货单：蓉经手
A29: 45378 | B29: 入库：贾总带来 | C29: 1206树脂 | D29: 1 | E29: 190 | F29: =E29*D29 -> 190
A30: 45411 | B30: 广汉 | C30: 五星花印方桶 | D30: 980 | E30: 1 | F30: =E30*D30 -> 980 | G30: 11.5 | H30: =F30*G30 -> 11270
A31: 日期 | C31: 品名 | D31: 数量/件 | E31: 规格/kg | F31: 数量/KG
A32: 45418 | C32: 购108树脂：夏 | D32: 6 | E32: 190 | F32: =D32*E32 -> 1140
A33: 45418 | C33: 购中络黄色粉 | D33: 8 | E33: 25 | F33: =D33*E33 -> 200 | G33: 有托运单、无货单
A34: 45418 | C34: 购5RK大红粉 | D34: 2 | E34: 25 | F34: =D34*E34 -> 50 | G34: 有托运单、无货单
A35: 45422 | C35: 购三木108树脂 | D35: 4 | E35: 190 | F35: =D35*E35 -> 760 | G35: 老板经手
A36: 45427 | C36: 购715粉 | D36: 12 | E36: 25 | F36: =D36*E36 -> 300 | G36: 25.5
A37: 45427 | C37: 购730粉 | D37: 8 | E37: 25 | F37: =D37*E37 -> 200 | G37: 25.5
A38: 45428 | C38: 购730粉 | D38: 8 | E38: 25 | F38: =D38*E38 -> 200 | H38: 无单
A39: 45429 | C39: 聚酮粉：CF-120 | D39: 20 | E39: 25 | F39: =D39*E39 -> 500
A40: 45449 | C40: 购715粉 | D40: 12 | E40: 25 | F40: =D40*E40 -> 300
A41: 45449 | C41: 购730粉 | D41: 8 | E41: 25 | F41: =D41*E41 -> 200
...
